Workbook
Name Brebis: ANIMAL!$D$24:$D$26
Name Céréale: COUT!$Q$29:$Q$36
Name Divers: COUT!$Q$55:$Q$63
Name Fibres: COUT!$Q$82:$Q$89
Name Graines: COUT!$Q$45:$Q$53
Name Mél: FOURRAGE!A1
Name Melange: MELANGE!$A$1
Name Mes_concentrés: NOUVEAU!$R$22:$R$36
Name Minéraux: COUT!$Q$65:$Q$80
Name Tourteau: COUT!$Q$38:$Q$43

Sheet ALIMOVINS
B1: fabrice.ranoux@educagri.fr
B3: Rationnement des ovins
B4: Fabrice RANOUX - LYCEE AGRICOLE du BOURBONNAIS - BP 1721 - 03017 MOULINS cedex - Tous droits réservés
B10: Version utilisable avec Microsoft® Excel 2010 et au-delà
C11: Code de déverrouillage → ctrl

Sheet ACCUEIL
B2: ALIM'ovins(v. 5.1)
B3: Rationnement des ovins
B4: Fabrice RANOUX - Lycée Agricole du Bourbonnais - BP 1721 - 03017 MOULINS cedex - Tous droits réservés
C7: RATION | E7: Etablissement d'une ration | H7: Cliquez
C10: BILAN | E10: Bilan alimentaire et coût | H10: Cliquez
C13: COUT | E13: Formulation d'aliment et coût de concentré | H13: Cliquez
C16: PREVISION | E16: Prévision de la valeur alimentaire des aliments du commerce | H16: Cliquez
C19: ALIMENTS | E19: Saisie de mes nouveaux aliments | H19: Cliquez
C22: FOURRAGES | E22: Bilan fourrager du troupeau | H22: Cliquez
C25: AGNEAUX | E25: Besoins des agneaux à l'engrais | H25: Cliquez
C28: PATURAGE | E28: Jours d'avance de pâturage | H28: Cliquez
C30: Les saisies effectuent uniquement dans les cases "blanches"
C31: Les cases "bleues" correspondent à des menus déroulants

Sheet PREVISION
B2: ALIM'ovins(v. 5.1)
B3: Rationnement des ovins
C5: Prévision
A7: Prévision de la valeur alimentaire d'un concentré du commerce (à partir des constituants analytiques)
B9: Valeurs d'analyse pour 100 g | D9: Saisissez les constituants | I9: Valeurs calculées | M9: Valeurs d'analyse
B10: Calculs effectués à partir des équations INRA | I10: MS | J10: =IF(D12="","",100-D12) | K10: % | N10: Saisissez les constituants
B12: Humidité | F12: % | I12: UFL | J12: =IF(D12="","",((118+(0.256*D14)+(1.58*D16)-(1.02*D18)-(2.07*I27))*(J10/10000))*(C36/1000)) | M12: P (Phosphore) | O12: %
B14: Protéines Brutes (Matières Azotées Totales) | C14: MAT | F14: % | I14: UFV | J14: =IF(D12="","",((120+(0.214*D14)+(1.62*D16)-(1.19*D18)-(2.64*I27))*(J10/10000))*(C36/1000)) | M14: Ca (Calcium) | O14: %
B16: Matière Grasse (Lipides) | C16: MG | F16: % | I16: PDIA | J16: =IF(D12="","",C30*(J10/100)) | K16: g / kg | M16: Minéraux absorbables
B18: Cellulose Brute | C18: CB | F18: % | I18: PDIN | J18: =IF(D12="","",C31*(J10/100)) | K18: g / kg | M18: Pabs | N18: =IF(N12="","",N12*6.5) | O18: g/100 g
B20: Cendres Brutes (Matières Minérales) | C20: MM | F20: % | I20: PDIE | J20: =IF(D12="","",C32*(J10/100)) | K20: g / kg | M20: Ca abs | N20: =IF(N14="","",N14*4) | O20: g/100 g
J22: =IF(D22="","",D22*0.7) | K22: =IF(J22="","","g / kg brut")
B27: MAT | C27: =D14*10 -> 0 | I27: =IF(D14>25,6,IF(D14>20,4,2)) -> 2
B28: DE1 | C28: 34
B29: MANDE1 | C29: =C27*(1-(C28/100)) -> 0
B30: PDIA | C30: =(-0.211*C27)+(0.84*C29) -> 0
B31: PDIN | C31: =(0.507*C27)+(0.278*C29) -> 0
B32: PDIE | C32: =67.1-(0.22*C27)+(0.802*C29) -> 67.1
B33: MG | C33: =D16*10 -> 0
B34: CB | C34: =D18*10 -> 0
B35: MM | C35: =D20*10 -> 0
B36: MO | C36: =1000-C35 -> 1000
B37: EB

Sheet ANIMAL
B1: ALIM'ovins(v. 5.1)
B2: Rationnement des ovins
F4: Ration
C6: 1 Cliquez sur les flèches pour faire votre choix | L6: REPARTITION DES BESOINS | R6: =R8-R7 -> 0.34138499 | S6: =S8-S7 -> 0.29946052 | T6: =T8-T7 -> 85.498863 | U6: =U8-U7 -> 0.58560865
R7: =POWER(C23,0.75)*0.033 -> 0.79861501 | S7: =R7/R8 -> 0.70053948 | T7: =POWER(C23,0.75)*2.5 -> 60.501137 | U7: =T7/T8 -> 0.41439135
B8: Catégorie animal | C8: Brebis | E8: BESOINS ALIMENTAIRES | M8: U.F.L. | O8: P.D.I. | R8: =F16 -> 1.14 | S8: 1 | T8: =G16 -> 146 | U8: 1
B10: Poids vif | C10: =IF(C8="","",CONCATENATE(C23," kg")) -> 70 kg | E10: CATEGORIE | L10: en % des besoins totaux
E11: =CONCATENATE(C8," ",C10," ",C12," ",C14," ",C16) -> Brebis 70 kg Gestante Double Semaines - 3 à - 4 | L11: ENTRETIEN
B12: =IF(C8="Brebis traite","Production laitière",IF(C8="brebis","Stade physiologique","Objectifs")) -> Stade physiologique | C12: Gestante
L13: =CONCATENATE(ROUND(G16/F16,0)," g PDI/UF") -> 128 g PDI/UF
B14: =IF(C8="Brebis","Agnelage Etat","") -> Agnelage Etat | C14: Double | E14: APPORTS ALIMENTAIRES RECOMMANDES
E15: U.E.M | F15: U.F.L | G15: P.D.I. | H15: Pabs | I15: Caabs | L15: PRODUCTION
B16: =IF(C8="Brebis","Période (semaines)","") -> Période (semaines) | C16: Semaines - 3 à - 4 | E16: =IF(C8="","",VLOOKUP($E$11,$C$39:$I$393,3)) -> 1.71 | F16: =IF(C8="","",IF(VLOOKUP($E$11,$C$39:$I$393,4)="ND","ND",IF(E34=2,VLOOKUP($E$11,$C$39:$I$393,4),VLOOKUP($E$11,$C$39:$I$393,4)+0.2))) -> 1.14 | G16: =IF(C8="","",VLOOKUP($E$11,$C$39:$I$393,5)) -> 146 | H16: =IF(C8="","",VLOOKUP($E$11,$C$39:$I$393,6)) -> 3.2 | I16: =IF(C8="","",VLOOKUP($E$11,$C$39:$I$393,7)) -> 3.5
C17: ND: non disponible | E17: =CONCATENATE(ROUND(F16/E16,2)," UFL / UEM") -> 0.67 UFL / UEM | G17: =CONCATENATE(ROUND(G16/F16,0)," g PDI / UFL") -> 128 g PDI / UFL | I17: =CONCATENATE("Ca/P = ",ROUND(I16/H16,1)) -> Ca/P = 1.1
C23: 70 | I23: 30 kg
C24: Brebis | D24: =IF(C8="Brebis traite","0,5 l/jour",IF(C8="Brebis","Allaitante","Croissance")) -> Allaitante | E24: =IF(C12="Engrais","Mauvais état (1 - 1.5)",IF(C8="Bélier","",IF(C8="Agnelle","",IF(C8="Brebis traite","",IF(C12="Vide","Sans prise de poids - Entretien",IF(C12="gestante",D31,F31)))))) -> Semaines - 5 à - 6 | F24: =IF(C12="Engrais","GMQ 50 g/j",IF(C8="Bélier","",IF(C8="Agnelle","",IF(C8="Brebis traite","",IF(C12="Vide","Mauvais Etat (< 2,5)","Simple"))))) -> Simple | I24: 40 kg
C25: Bélier | D25: =IF(C8="Brebis traite","1,0 l/jour",IF(C8="Brebis","Gestante","Flushing")) -> Gestante | E25: =IF(C12="Engrais","Etat moyen (2 - 2.5)",IF(C8="Bélier","",IF(C8="Agnelle","",IF(C8="Brebis traite","",IF(C12="Vide","Avec prise de poids + 150 g/j",IF(C12="gestante",D32,F32)))))) -> Semaines - 3 à - 4 | F25: =IF(C12="Engrais","GMQ 100 g/j",IF(C8="Bélier","",IF(C8="Agnelle","",IF(C8="Brebis traite","",IF(C12="Vide","Etat Moyen (2,5 - 3,5)","Double"))))) -> Double | I25: 50 kg | J25: 30 kg | K25: 70 kg
C26: Agnelle | D26: =IF(C8="Brebis traite","2,0 l/jour",IF(C8="Brebis","Vide","Entretien")) -> Vide | E26: =IF(C12="Engrais","Bon état (3 - 3.5)",IF(C8="Bélier","",IF(C8="Agnelle","",IF(C8="Brebis traite","",IF(C12="Vide","flushing + 100 g/j",IF(C12="gestante",D33,F33)))))) -> Semaines - 2 à 0 | F26: =IF(C12="Engrais","GMQ 150 g/j",IF(C8="Bélier","",IF(C8="Agnelle","",IF(C8="Brebis traite","",IF(C12="Vide","Bon Etat (> 3,5)",IF(C12="Allaitante","Triple","Inconnu")))))) -> Inconnu | I26: 60 kg | J26: 40 kg | K26: 80 kg
C27: Brebis traite | D27: =IF(C8="Brebis traite","2,5 l/jour",IF(C8="Brebis","Engrais","")) -> Engrais | I27: 70 kg | J27: 50 kg | K27: 90 kg
D28: =IF(C8="Brebis traite","3,0 l/jour","") | I28: 80 kg | K28: 100 kg
C29: 60 kg | D29: =IF(C8="Brebis traite","3,5 l/jour","") | I29: 90 kg
C30: =IF($C$9="brebis",I25,IF($C$9="Agnelle",J25,K25)) -> 70 kg | I30: 100 kg
C31: =IF($C$9="brebis",I26,IF($C$9="Agnelle",J26,K26)) -> 80 kg | D31: Semaines - 5 à - 6 | F31: Semaines 0 à + 3
C32: =IF($C$9="brebis",I27,IF($C$9="Agnelle",J27,K27)) -> 90 kg | D32: Semaines - 3 à - 4 | F32: Semaines + 4 à + 6
C33: =IF($C$9="brebis",I28,IF($C$9="Agnelle",J28,K28)) -> 100 kg | D33: Semaines - 2 à 0 | F33: Semaines + 7 à + 10 | I33: Bergerie
E34: 2 | I34: Plein air
C38: Catégorie | E38: UEM | F38: UFL | G38: PDI | H38: Pabs | I38: Caabs
C39: Agnelle 100 kg Croissance | E39: ND | F39: ND | G39: ND | H39: ND | I39: ND
C40: Agnelle 100 kg Entretien | E40: ND | F40: ND | G40: ND | H40: ND | I40: ND
C41: Agnelle 100 kg Flushing | E41: ND | F41: ND | G41: ND | H41: ND | I41: ND
C42: Agnelle 30 kg Croissance | D42: 13 | E42: 1 | F42: 0.57 | G42: 52 | H42: 0.9 | I42: 1
C43: Agnelle 30 kg Entretien | D43: 15 | E43: 1 | F43: 0.44 | G43: 32 | H43: 0.6 | I43: 0.8
C44: Agnelle 30 kg Flushing | D44: 14 | E44: 1 | F44: 1 | G44: 54 | H44: 0.6 | I44: 0.8
C45: Agnelle 40 kg Croissance | D45: 16 | E45: 1.2 | F45: 0.78 | G45: 62 | H45: 1.4 | I45: 1.5
C46: Agnelle 40 kg Entretien | D46: 18 | E46: 1.2 | F46: 0.52 | G46: 40 | H46: 0.8 | I46: 1
C47: Agnelle 40 kg Flushing | D47: 17 | E47: 1.2 | F47: 1.08 | G47: 62 | H47: 0.8 | I47: 1
C48: Agnelle 50 kg Croissance | D48: 19 | E48: 1.3 | F48: 0.84 | G48: 69 | H48: 1.6 | I48: 1.7
C49: Agnelle 50 kg Entretien | D49: 21 | E49: 1.3 | F49: 0.62 | G49: 47 | H49: 1 | I49: 1.2
C50: Agnelle 50 kg Flushing | D50: 20 | E50: 1.3 | F50: 0.84 | G50: 69 | H50: 1 | I50: 1.2
C51: Agnelle 60 kg Croissance | E51: ND | F51: ND | G51: ND | H51: ND | I51: ND
...

Sheet FOURRAGE
B1: ALIM'ovins(v. 5.1)
B2: Rationnement des ovins
H4: Ration
B5: zone de Plaine (Normandie) zone de Demi-montagne (Auvergne)
E6: FOURRAGE N° 1 (Rationné ou à volonté) | K6: 2 Saisissez les quantités brutes ou cliquez A VOLONTE
O7: =IF(ANIMAL!C8="","",IF(O11>1,"ATTENTION ! La capacité d'ingestion est dépassée",IF(C9="","",IF(V7<0.02,"La capacité d'ingestion est atteinte","La capacité d'ingestion n'est pas atteinte")))) -> ATTENTION ! La capacité d'ingestion est dépassée | U7: =ANIMAL!E16 -> 1.71 | V7: =IF(O11>1,0,1-V9-V8) -> 0
B8: 1 Cliquez sur les flèches pour faire votre choix | U8: =IF(C23="",0,L24*(E29/100)*F29) -> 0 | V8: =IF(O11>1,0,U8/U7) -> 0
B9: Catégorie fourrage | E9: =CONCATENATE(C9," ",C11," ",C13," ",C15) | O9: Capacité d'ingestion | T9: =U12/U7 -> 0 | U9: =IF(C9="",0,(L10*(E15/100)*F15)) -> 0 | V9: =IF(O11>1,0,U9/U7) -> 0
Q10: =IF(O11="","",IF(O11>1,"Réduisez les fourrages !",""))
B11: Espèce végétale | O11: =IF(C9="","",T9)
O12: =IF(C23="","",C23) | Q12: =IF(C23="","",2) | U12: =U9+U8 -> 0 | V12: =U12/U7 -> 0
B13: Conditions de récolte | E13: Valeurs Alimentaires
E14: % M.S. | F14: U.E.M. | G14: U.F.L | H14: P.D.I.N. | I14: P.D.I.E. | J14: Pabs | L14: Caabs | O14: =IF(C9="","",C9) | Q14: =IF(C9="","",1)
B15: Stade physiologique | E15: =IF(B42=1,IF(C9="","",IF(C9="Mon fourrage",VLOOKUP($C$11,NOUVEAU!$E$22:$N30,3),VLOOKUP($E$9,$C$78:L246,2))),IF(C9="","",IF(C9="Mon fourrage",VLOOKUP($C$11,NOUVEAU!$E$22:$N30,3),VLOOKUP($E$9,$C$259:L433,2)))) | F15: =IF(B42=1,IF(C9="","",IF(C9="Mon fourrage",VLOOKUP($C$11,NOUVEAU!$E$22:$N30,4),VLOOKUP($E$9,$C$78:M246,3))),IF(C9="","",IF(C9="Mon fourrage",VLOOKUP($C$11,NOUVEAU!$E$22:$N30,4),VLOOKUP($E$9,$C$259:M433,3)))) | G15: =IF(B42=1,IF(C9="","",IF(C9="Mon fourrage",VLOOKUP($C$11,NOUVEAU!$E$22:$N30,5),VLOOKUP($E$9,$C$78:N246,5))),IF(C9="","",IF(C9="Mon fourrage",VLOOKUP($C$11,NOUVEAU!$E$22:$N30,5),VLOOKUP($E$9,$C$259:N433,5)))) | H15: =IF(B42=1,IF(C9="","",IF(C9="Mon fourrage",VLOOKUP($C$11,NOUVEAU!$E$22:$N30,7),VLOOKUP($E$9,$C$78:O246,7))),IF(C9="","",IF(C9="Mon fourrage",VLOOKUP($C$11,NOUVEAU!$E$22:$N30,7),VLOOKUP($E$9,$C$259:O433,7)))) | I15: =IF(B42=1,IF(C9="","",IF(C9="Mon fourrage",VLOOKUP($C$11,NOUVEAU!$E$22:$N30,8),VLOOKUP($E$9,$C$78:P246,8))),IF(C9="","",IF(C9="Mon fourrage",VLOOKUP($C$11,NOUVEAU!$E$22:$N30,8),VLOOKUP($E$9,$C$259:P433,8)))) | J15: =IF(B42=1,IF(C9="","",IF(C9="Mon fourrage",VLOOKUP($C$11,NOUVEAU!$E$22:$N30,9),VLOOKUP($E$9,$C$78:Q246,9))),IF(C9="","",IF(C9="Mon fourrage",VLOOKUP($C$11,NOUVEAU!$E$22:$N30,9),VLOOKUP($E$9,$C$259:Q433,9)))) | K15: =IF(B9="","",IF(B9="Mon fourrage",VLOOKUP($C$11,NOUVEAU!$E$22:$N31,10),VLOOKUP($E$9,$C$78:R246,10))) -> #N/A | L15: =IF(B42=1,IF(C9="","",IF(C9="Mon fourrage",VLOOKUP($C$11,NOUVEAU!$E$22:$N30,10),VLOOKUP($E$9,$C$78:S246,10))),IF(C9="","",IF(C9="Mon fourrage",VLOOKUP($C$11,NOUVEAU!$E$22:$N30,10),VLOOKUP($E$9,$C$259:S433,10))))
E16: ND: non disponible
E20: FOURRAGE N° 2 (Rationné)
B21: 1 Cliquez sur les flèches pour faire votre choix | K21: 3 Saisissez les quantités brutes | O21: Densité énergétique de la ration minimale
B23: Catégorie fourrage | E23: =CONCATENATE(C23," ",C25," ",C27," ",C29) | O23: DERm | Q23: =IF(ANIMAL!C8="","",ANIMAL!F16/ANIMAL!E16) -> 0.66666667
B25: Espèce végétale | O25: =IF(C23="","",IF(Q23>Q27,">","<")) | P25: Densité énergétique du fourrage
B27: Conditions de récolte | E27: Valeurs Alimentaires | O27: DEF | Q27: =IF(C9="","",IF(L24="",G15/F15,AVERAGE((G15/F1),(G29/F29))))
E28: % M.S. | F28: U.E.M | G28: U.F.L | H28: P.D.I.N. | I28: P.D.I.E. | J28: Pabs | L28: Caabs | O28: =IF(C9="","",IF(Q23>Q27,"Il faut ajouter un concentré","Un concentré n'est pas nécessaire"))
B29: Stade physiologique | E29: =IF(B42=1,IF(C23="","",IF(C23="Mon fourrage",VLOOKUP($C$25,NOUVEAU!$E$22:$N30,3),VLOOKUP($E$23,$C$78:L246,2))),IF(C23="","",IF(C23="Mon fourrage",VLOOKUP($C$25,NOUVEAU!$E$22:$N30,3),VLOOKUP($E$23,$C$259:L433,2)))) | F29: =IF(B42=1,IF(C23="","",IF(C23="Mon fourrage",VLOOKUP($C$25,NOUVEAU!$E$22:$N30,4),VLOOKUP($E$23,$C$78:M246,3))),IF(C23="","",IF(C23="Mon fourrage",VLOOKUP($C$25,NOUVEAU!$E$22:$N30,4),VLOOKUP($E$23,$C$259:M433,3)))) | G29: =IF(B42=1,IF(C23="","",IF(C23="Mon fourrage",VLOOKUP($C$25,NOUVEAU!$E$22:$N30,5),VLOOKUP($E$23,$C$78:N246,5))),IF(C23="","",IF(C23="Mon fourrage",VLOOKUP($C$25,NOUVEAU!$E$22:$N30,5),VLOOKUP($E$23,$C$259:N433,5)))) | H29: =IF(B42=1,IF(C23="","",IF(C23="Mon fourrage",VLOOKUP($C$25,NOUVEAU!$E$22:$N30,7),VLOOKUP($E$23,$C$78:O246,7))),IF(C23="","",IF(C23="Mon fourrage",VLOOKUP($C$25,NOUVEAU!$E$22:$N30,7),VLOOKUP($E$23,$C$259:O433,7)))) | I29: =IF(B42=1,IF(C23="","",IF(C23="Mon fourrage",VLOOKUP($C$25,NOUVEAU!$E$22:$N30,8),VLOOKUP($E$23,$C$78:P246,8))),IF(C23="","",IF(C23="Mon fourrage",VLOOKUP($C$25,NOUVEAU!$E$22:$N30,8),VLOOKUP($E$23,$C$259:P433,8)))) | J29: =IF(B42=1,IF(C23="","",IF(C23="Mon fourrage",VLOOKUP($C$25,NOUVEAU!$E$22:$N30,9),VLOOKUP($E$23,$C$78:Q246,9))),IF(C23="","",IF(C23="Mon fourrage",VLOOKUP($C$25,NOUVEAU!$E$22:$N30,9),VLOOKUP($E$23,$C$259:Q433,9)))) | L29: =IF(B42=1,IF(C23="","",IF(C23="Mon fourrage",VLOOKUP($C$25,NOUVEAU!$E$22:$N30,10),VLOOKUP($E$23,$C$78:S246,10))),IF(C23="","",IF(C23="Mon fourrage",VLOOKUP($C$25,NOUVEAU!$E$22:$N30,10),VLOOKUP($E$23,$C$259:S433,10))))
E30: ND: non disponible
J40: =IF($C$9="Mon fourrage",NOUVEAU!E22,IF($C$9="Paille",Q40,IF($C$9="Ensilage",L40,IF($C$9="Pâture",S40,O40)))) -> Prairie naturelle | L40: Prairie naturelle | O40: Prairie naturelle | Q40: Blé | S40: Pré | U40: Déprimage
B41: =IF(L24="",0,L24*(E29/100)*F29) -> 0 | J41: =IF($C$9="Mon fourrage",NOUVEAU!E23,IF($C$9="Paille",Q41,IF($C$9="Ensilage",L41,IF($C$9="Pâture",S41,O41)))) -> Fétuque élevée | L41: Fétuque | O41: Fétuque élevée | Q41: Orge | S41: Colza fourrager | U41: Printemps
B42: 1 | E42: =IF($C$9="Mon Fourrage","",IF($C$9="Pâture","Déprimage",IF($C$9="Paille","",IF($C$11="Maïs","",L50)))) -> 1er cycle début épiaison (25/05) | J42: =IF($C$9="Mon fourrage",NOUVEAU!E24,IF($C$9="Paille",Q42,IF($C$9="Ensilage",L42,IF($C$9="Pâture",S42,O42)))) -> Luzerne-Dactyle | L42: Luzerne-Dactyle | O42: Luzerne-Dactyle | Q42: Triticale | S42: Betterave (distribuée) | U42: Fin Printemps
C43: Foin | E43: =IF($C$9="Mon Fourrage","",IF($C$9="Pâture","Printemps",IF($C$9="Paille","",IF($C$11="Maïs","",L51)))) -> 1er cycle épaison (10/06) | J43: =IF($C$9="Mon fourrage",NOUVEAU!E25,IF($C$9="Paille",Q43,IF($C$9="Ensilage",L43,IF($C$9="Pâture",S43,O43)))) -> Trèfle-Ray Grass | L43: Trèfle-Ray Grass | O43: Trèfle-Ray Grass | Q43: Avoine | S43: Vesce | U43: Repousses
C44: Ensilage | E44: =IF($C$9="Mon Fourrage","",IF($C$9="Pâture","Fin Printemps",IF($C$9="Paille","",IF($C$11="Maïs","",L52)))) -> 1er cycle début floraison (20/06) | J44: =IF($C$9="Mon fourrage",NOUVEAU!E26,IF($C$9="Paille",Q44,IF($C$9="Ensilage",L44,IF($C$9="Pâture",S44,O44)))) -> Ray Grass Italien | L44: Ray Grass Italien | O44: Ray Grass Italien | Q44: Paille traitée Ammoniac | S44: Trèfle blanc
C45: Paille | E45: =IF($C$9="Mon Fourrage","",IF($C$9="Pâture","Repousse",IF($C$9="Paille","",IF($C$11="Maïs","",L53)))) -> 2ème cycle (regain) | J45: =IF($C$9="Mon fourrage",NOUVEAU!E27,IF($C$9="Paille",Q45,IF($C$9="Ensilage",L45,IF($C$9="Pâture",S45,O45)))) -> Luzerne | L45: Luzerne | O45: Luzerne | S45: Avoine
C46: Pâture | E46: =IF($C$9="Mon Fourrage","",IF($C$9="Pâture","Dérobé",IF($C$9="Paille","",IF($C$11="Maïs","",L54)))) | J46: =IF($C$9="Mon fourrage",NOUVEAU!E28,IF($C$9="Paille",Q46,IF($C$9="Ensilage",L46,IF($C$9="Pâture",S46,O46)))) | L46: Maïs | S46: Navet
C47: Mon fourrage | E47: =IF($C$9="Mon Fourrage","",IF($C$9="Pâture","",IF($C$9="Paille","",IF($C$11="Maïs","",L55))))
D50: Ventilé (en grange) | G50: Ressuyage (25 % MS) | L50: 1er cycle début épiaison (25/05) | P50: Mauvaises conditions < 30 % MS
C51: =IF($C$9="Mon Fourrage","",IF($C$9="Pâture","",IF($C$9="Foin",D50,IF($C$9="Paille","",IF($C$11="Maïs",P50,G50))))) -> Ressuyage (25 % MS) | D51: Fané au sol par beau temps | G51: Préfané (35 % MS) | L51: 1er cycle épaison (10/06) | P51: Conditions normales 25 % MS
C52: =IF($C$9="Mon Fourrage","",IF($C$9="Pâture","",IF($C$9="Foin",D51,IF($C$9="Paille","",IF($C$11="Maïs",P51,G51))))) -> Préfané (35 % MS) | D52: Fané au sol < 10 jours) | G52: Enrubanné (> 45 % MS) | L52: 1er cycle début floraison (20/06) | P52: Conditions normales 30 % MS
C53: =IF($C$9="Mon Fourrage","",IF($C$9="Pâture","",IF($C$9="Foin",D52,IF($C$9="Paille","",IF($C$11="Maïs",P52,G52))))) -> Enrubanné (> 45 % MS) | L53: 2ème cycle (regain) | P53: Conditions normales 35 % MS
C54: =IF($C$9="Mon Fourrage","",IF($C$9="Pâture","",IF($C$9="Foin",D53,IF($C$9="Paille","",IF($C$11="Maïs",P53,G53))))) | P54: Très bonnes conditions (> 35 % MS)
C55: =IF($C$9="Mon Fourrage","",IF($C$9="Pâture","",IF($C$9="Foin",D54,IF($C$9="Paille","",IF($C$11="Maïs",P54,G54))))) | E55: Fourrage 1
C56: =IF($C$9="Pâture","",IF($C$9="Foin",D55,IF($C$9="Paille","",IF($C$11="Maïs",P55,G55)))) | E56: Fourrage 2
E57: Fourrage 3 | J57: =IF($C$23="mon fourrage",NOUVEAU!E22,IF($C$23="Paille",Q57,IF($C$23="Ensilage",L57,IF($C$23="Pâture",S57,O57)))) -> Prairie naturelle | L57: Prairie naturelle | O57: Prairie naturelle | Q57: Blé | S57: Pré | U57: Déprimage
J58: =IF($C$23="mon fourrage",NOUVEAU!E23,IF($C$23="Paille",Q58,IF($C$23="Ensilage",L58,IF($C$23="Pâture",S58,O58)))) -> Fétuque élevée | L58: Fétuque | O58: Fétuque élevée | Q58: Orge | S58: Colza fourrager | U58: Printemps
...

Sheet CONCENTRE
B1: ALIM'ovins(v. 5.1)
B2: Rationnement des ovins
I4: Ration
J5: 3 Saisissez les quantités brutes distribuées ou cliquez sur "Mélange"
B6: 1 Cliquez sur les flèches pour faire votre choix | E6: CONCENTRE N°1 | N6: Valeurs des concentrés
N7: =IF(K9="","",C10) | O7: =IF(K16="","",C17) | T7: =K16/(K9+K16) -> #DIV/0!
B8: Catégorie | E8: Valeurs alimentaires / kg brut | T8: =K9/(K9+K16) -> #DIV/0!
E9: U.F.L. | F9: P.D.I.N. | G9: P.D.I.E. | H9: Pabs | I9: Caabs | S9: =IF(C8="",0,IF(K16="",1,(K9*E10)/((K9*E10)+(E17*K16)))) -> 0 | T9: =IF(C8="",0,IF(K16="",1,(K9*F10)/((K9*F10)+(F17*K16)))) -> 0
B10: Espèce | E10: =IF(C8="Mélange fermier",COUT!F23,IF(C8="","",IF($C$8="Mon concentré",VLOOKUP($C$10,NOUVEAU!R22:AA35,3),VLOOKUP($C$10,$C$42:$I$79,3)))) | F10: =IF(C8="Mélange fermier",COUT!H23,IF(C8="","",IF($C$8="Mon concentré",VLOOKUP($C$10,NOUVEAU!R22:AA35,5),VLOOKUP($C$10,$C$42:$I$79,4)))) | G10: =IF(C8="Mélange fermier",COUT!I23,IF(C8="","",IF($C$8="Mon concentré",VLOOKUP($C$10,NOUVEAU!R22:AA35,6),VLOOKUP($C$10,$C$42:$I$79,5)))) | H10: =IF(C8="Mélange fermier",COUT!J23,IF(C8="","",IF($C$8="Mon concentré",VLOOKUP($C$10,NOUVEAU!R22:AA35,7),VLOOKUP($C$10,$C$42:$I$79,6)))) | I10: =IF(C8="Mélange fermier",COUT!K23,IF(C8="","",IF($C$8="Mon concentré",VLOOKUP($C$10,NOUVEAU!R22:AA35,8),VLOOKUP($C$10,$C$42:$I$79,7)))) | S10: =IF(C15="",0,IF(K9="",1,(K16*E17)/((K16*E17)+(K9*E10)))) -> 0 | T10: =IF(C15="",0,IF(K9="",1,(K16*F17)/((K16*F17)+(K9*F10)))) -> 0
O11: UFL | Q11: PDIN
B13: 2 Cliquez sur les flèches pour faire votre choix | E13: CONCENTRE N°2 | N13: =IF(K9="","","Concentré 1")
N14: =IF(K9="","",C10)
B15: Catégorie | E15: Valeurs alimentaires / kg brut
E16: U.F.L. | F16: P.D.I.N. | G16: P.D.I.E. | H16: Pabs | I16: Caabs | N16: =IF(K16="","","Concentré 2")
B17: Espèce | E17: =IF(C15="Mélange fermier",COUT!F23,IF(C15="","",IF($C$15="Mon concentré",VLOOKUP($C$17,NOUVEAU!R22:AA45,3),VLOOKUP($C$17,$C$42:$I$79,3)))) | F17: =IF(C15="Mélange fermier",COUT!H23,IF(C15="","",IF($C$15="Mon concentré",VLOOKUP($C$17,NOUVEAU!R22:AA45,5),VLOOKUP($C$17,$C$42:$I$79,4)))) | G17: =IF(C15="Mélange fermier",COUT!I23,IF(C15="","",IF($C$15="Mon concentré",VLOOKUP($C$17,NOUVEAU!R22:AA45,6),VLOOKUP($C$17,$C$42:$I$79,5)))) | H17: =IF(C15="Mélange fermier",COUT!J23,IF(C15="","",IF($C$15="Mon concentré",VLOOKUP($C$17,NOUVEAU!R22:AA45,7),VLOOKUP($C$17,$C$42:$I$79,6)))) | I17: =IF(C15="Mélange fermier",COUT!K23,IF(C15="","",IF($C$15="Mon concentré",VLOOKUP($C$17,NOUVEAU!R22:AA45,8),VLOOKUP($C$17,$C$42:$I$79,7)))) | N17: =IF(K16="","",C17)
E22: =IF($C$8="Mélange fermier","Mélange fermier",IF($C$8="Céréale",F22,IF($C$8="Tourteau",G22,IF($C$8="Divers",K22,IF($C$8="Mon concentré",NOUVEAU!R22,I22))))) -> Pois | F22: Blé | G22: Colza 35 | I22: Pois | K22: Drêches de brasserie
C23: Céréale | E23: =IF($C$8="Mélange fermier","",IF($C$8="Céréale",F23,IF($C$8="Tourteau",G23,IF($C$8="Divers",K23,IF($C$8="Mon concentré",NOUVEAU!R23,I23))))) -> Lupin | F23: Orge | G23: Soja 48 | I23: Lupin | K23: Graines de Colza
C24: Tourteau | E24: =IF($C$8="Mélange fermier","",IF($C$8="Céréale",F24,IF($C$8="Tourteau",G24,IF($C$8="Divers",K24,IF($C$8="Mon concentré",NOUVEAU!R24,I24))))) -> Féverole | F24: Avoine | G24: Tournesol | I24: Féverole | K24: Drêches de blé
C25: Protéagineux | E25: =IF($C$8="Mélange fermier","",IF($C$8="Céréale",F25,IF($C$8="Tourteau",G25,IF($C$8="Divers",K25,IF($C$8="Mon concentré",NOUVEAU!R25,I25))))) -> Vesce | F25: Triticale | G25: Lin | I25: Vesce | K25: Huile de Colza
C26: Divers | E26: =IF($C$8="Mélange fermier","",IF($C$8="Céréale",F26,IF($C$8="Tourteau",G26,IF($C$8="Divers",K26,IF($C$8="Mon concentré",NOUVEAU!R26,I26))))) -> Soja extrudé | F26: Seigle | G26: Arachide | I26: Soja extrudé | K26: Luzerne deshydratée
C27: Mon concentré | E27: =IF($C$8="Mélange fermier","",IF($C$8="Céréale",F27,IF($C$8="Tourteau",G27,IF($C$8="Divers",K27,IF($C$8="Mon concentré",NOUVEAU!R27,I27))))) | F27: Maïs grain | G27: Coton déshuilé | K27: Mélasse
C28: Mélange fermier | E28: =IF($C$8="Mélange fermier","",IF($C$8="Céréale",F28,IF($C$8="Tourteau",G28,IF($C$8="Divers",K28,IF($C$8="Mon concentré",NOUVEAU!R28,I28))))) | F28: Sarrazin | G28: Tournesol décortiqué | K28: Lait écrémé en poudre
E29: =IF($C$8="Mélange fermier","",IF($C$8="Céréale",F29,IF($C$8="Tourteau",G29,IF($C$8="Divers",K29,IF($C$8="Mon concentré",NOUVEAU!R29,I29))))) | F29: Sorgho | G29: Soja tanné | K29: Pulpe de Betterave
E31: =IF($C$15="Mélange fermier","Mélange fermier",IF($C$15="Céréale",F31,IF($C$15="Tourteau",G31,IF($C$15="Divers",K31,IF($C$15="Mon concentré",NOUVEAU!R22,I31))))) -> Pois | F31: Blé | G31: Colza 35 | I31: Pois | K31: Drêches de brasserie
C32: Céréale | E32: =IF($C$15="Mélange fermier","",IF($C$15="Céréale",F32,IF($C$15="Tourteau",G32,IF($C$15="Divers",K32,IF($C$15="Mon concentré",NOUVEAU!R23,I32))))) -> Lupin | F32: Orge | G32: Soja 48 | I32: Lupin | K32: Graines de Colza
C33: Tourteau | E33: =IF($C$15="Mélange fermier","",IF($C$15="Céréale",F33,IF($C$15="Tourteau",G33,IF($C$15="Divers",K33,IF($C$15="Mon concentré",NOUVEAU!R24,I33))))) -> Féverole | F33: Avoine | G33: Tournesol | I33: Féverole | K33: Drêches de blé
C34: Protéagineux | E34: =IF($C$15="Mélange fermier","",IF($C$15="Céréale",F34,IF($C$15="Tourteau",G34,IF($C$15="Divers",K34,IF($C$15="Mon concentré",NOUVEAU!R25,I34))))) -> Vesce | F34: Triticale | G34: Lin | I34: Vesce | K34: Huile de Colza
C35: Divers | E35: =IF($C$15="Mélange fermier","",IF($C$15="Céréale",F35,IF($C$15="Tourteau",G35,IF($C$15="Divers",K35,IF($C$15="Mon concentré",NOUVEAU!R26,I35))))) -> Soja extrudé | F35: Seigle | G35: Arachide | I35: Soja extrudé | K35: Luzerne deshydratée
C36: Mes aliments | E36: =IF($C$15="Mélange fermier","",IF($C$15="Céréale",F36,IF($C$15="Tourteau",G36,IF($C$15="Divers",K36,IF($C$15="Mon concentré",NOUVEAU!R27,I36))))) | F36: Maïs grain | G36: Coton déshuilé | K36: Mélasse
E37: =IF($C$15="Mélange fermier","",IF($C$15="Céréale",F37,IF($C$15="Tourteau",G37,IF($C$15="Divers",K37,IF($C$15="Mon concentré",NOUVEAU!R28,I37))))) | F37: Sarrazin | G37: Tournesol décortiqué | K37: Lait écrémé en poudre
E38: =IF($C$15="Mélange fermier","",IF($C$15="Céréale",F38,IF($C$15="Tourteau",G38,IF($C$15="Divers",K38,IF($C$15="Mon concentré",NOUVEAU!R29,I38))))) | F38: Sorgho | G38: Soja tanné | K38: Pulpe de Betterave
C41: Catégorie | D41: C | E41: U.F.L. | F41: P.D.I.N. | G41: P.D.I.E. | H41: Pabs | I41: Caabs
C42: Arachide | D42: 90 | E42: 1 | F42: 347 | G42: 215 | H42: =K42*(D42/100) -> 3.69 | I42: =N42*(D42/100) -> 1.08 | K42: 4.1 | N42: 1.2
C43: Avoine | D43: 88 | E43: 0.77 | F43: 61 | G43: 61 | H43: =K43*(D43/100) -> 2.376 | I43: =N43*(D43/100) -> 0.616 | K43: 2.7 | N43: 0.7
C44: Blé | D44: 87 | E44: 1.02 | F44: 70 | G44: 89 | H44: =K44*(D44/100) -> 2.262 | I44: =N44*(D44/100) -> 0.348 | K44: 2.6 | N44: 0.4
C45: Colza 35 | D45: 89 | E45: 0.85 | F45: 219 | G45: 138 | H45: =K45*(D45/100) -> 8.188 | I45: =N45*(D45/100) -> 4.628 | K45: 9.2 | N45: 5.2
C46: Colza tanné | E46: 0.85 | F46: 255 | G46: 246 | H46: 9.2 | I46: 5.2
C47: Corn gluten | E47: 0.93 | F47: 127 | G47: 102 | H47: 6.8 | I47: 1
C48: Coton | D48: 91 | E48: 0.94 | F48: 131 | G48: 77 | H48: =K48*(D48/100) -> 4.641 | I48: =N48*(D48/100) -> 0.91 | K48: 5.1 | N48: 1
C49: Coton déshuilé | E49: 0.8 | F49: 254 | G49: 173 | H49: 7.9 | I49: 1.5
...

Sheet CMV
B1: ALIM'ovins(v. 5.1)
B2: Rationnement des ovins
I4: Ration
B6: Choisir le C.M.V. ayant le rapport "Ca / P" le plus approchant du déficit | P6: Pabs | Q6: Caabs
C7: 1 Cliquez sur les flèches pour choisir le CMV | G7: Ca / P ration (avant correction) | L7: C.M.V. choisi | O7: 100 % des A.A.R. | U7: =ANIMAL!H16 -> 3.2 | V7: =ANIMAL!I16 -> 3.5
B8: Type | G8: =IF(L24=TRUE,"Un CMV n'est pas nécessaire",IF(L14="","",IF(L12<0.2,"Utilisez un CMV pauvre en P",CONCATENATE("Utilisez un CMV avec ",INT(1.63*(L14/L12))," fois plus de Ca que de P")))) -> Utilisez un CMV avec 1 fois plus de Ca que de P | L8: =CONCATENATE("C.M.V.",C8) -> C.M.V. | O8: Avant correction | U8: =IF(RATION!I24="",RATION!I16,RATION!I16+RATION!I24) | V8: =IF(RATION!J24="",RATION!J16,RATION!J16+RATION!J24)
T10: 0 | U10: =U8/U7 -> #VALUE! | V10: =V8/V7 -> #VALUE! | W10: 0
B11: 2 Saisir la quantité de CMV choisie ou accepter la quantité proposée | L11: Déficit Pabs | P11: =IF(L12="","",U10) -> #VALUE! | R11: =IF(L14="","",V10) -> #VALUE! | T11: 1 | U11: 1 | V11: 1 | W11: 1
D12: g. | G12: Valeurs alimentaires / kg brut | L12: =IF(ANIMAL!C8="","",IF(SUM(RATION!I24,RATION!I16)-RATION!I8>=0,0,-(SUM(RATION!I24,RATION!I16)-RATION!I8))) -> 3.2 | O12: 100 % des A.A.R.
G13: Pabs | I13: Caabs | L13: Déficit Caabs | T13: =IF(C8="",0,(C12/1000)*G14) -> 0 | U13: =T13+U8 -> #VALUE! | V13: 0 | W13: =U13/U7 -> #VALUE! | X13: =U14/V7 -> #VALUE!
B14: Ca / P | C14: =IF(C8="","",IF(VLOOKUP(C8,C20:H40,4)>10,"ns",VLOOKUP(C8,C20:H40,4))) | E14: =IF(C8="","",G42) | G14: =IF(C8="","",VLOOKUP(C8,C20:H40,5)) | I14: =IF(C8="","",VLOOKUP(C8,C20:H40,6)) | L14: =IF(ANIMAL!C8="","",IF(SUM(RATION!J24,RATION!J16)-RATION!J8>=0,0,-(SUM(RATION!J24,RATION!J16)-RATION!J8))) -> 3.5 | O14: Après correction | T14: =IF(C8="",0,(C12/1000)*I14) -> 0 | U14: =T14+V8 -> #VALUE! | V14: 1 | W14: 1 | X14: 1
C16: =IF(C8="","",IF(E14<10,"Un CMV n'est pas nécessaire - Cliquez sur Valider sans rien saisir","")) | P16: =IF(L12="","",W13) -> #VALUE! | R16: =IF(L14="","",X13) -> #VALUE!
C20: 0 - 27 | F20: =J20/I20 -> 2700 | G20: 0.1 | H20: =J20*0.4 -> 108 | I20: 0.1 | J20: 270
C21: 10 - 20 | F21: =J21/I21 -> 2 | G21: =I21*0.65 -> 65 | H21: =J21*0.4 -> 80 | I21: 100 | J21: 200
C22: 10 - 6 | F22: =J22/I22 -> 0.6 | G22: =I22*0.65 -> 65 | H22: =J22*0.4 -> 24 | I22: 100 | J22: 60
C23: 12 - 12 | F23: =J23/I23 -> 1 | G23: =I23*0.65 -> 78 | H23: =J23*0.4 -> 48 | I23: 120 | J23: 120
C24: 2 - 28 | F24: =J24/I24 -> 14 | G24: =I24*0.65 -> 13 | H24: =J24*0.4 -> 112 | I24: 20 | J24: 280 | L24: =AND(L12<0.2,L14<0.2) -> FALSE
C25: 3 - 27 | F25: =J25/I25 -> 9 | G25: =I25*0.65 -> 19.5 | H25: =J25*0.4 -> 108 | I25: 30 | J25: 270
C26: 4 - 21 | F26: =J26/I26 -> 5.25 | G26: =I26*0.65 -> 26 | H26: =J26*0.4 -> 84 | I26: 40 | J26: 210
C27: 5 - 20 | F27: =J27/I27 -> 4 | G27: =I27*0.65 -> 32.5 | H27: =J27*0.4 -> 80 | I27: 50 | J27: 200
C28: 5 - 22 | F28: =J28/I28 -> 4.4 | G28: =I28*0.65 -> 32.5 | H28: =J28*0.4 -> 88 | I28: 50 | J28: 220
C29: 5 - 25 | F29: =J29/I29 -> 5 | G29: =I29*0.65 -> 32.5 | H29: =J29*0.4 -> 100 | I29: 50 | J29: 250
C30: 6 - 18 | F30: =J30/I30 -> 3 | G30: =I30*0.65 -> 39 | H30: =J30*0.4 -> 72 | I30: 60 | J30: 180
C31: 6 - 6 | F31: =J31/I31 -> 1 | G31: =I31*0.65 -> 39 | H31: =J31*0.4 -> 24 | I31: 60 | J31: 60
C32: 7 - 21 | F32: =J32/I32 -> 3 | G32: =I32*0.65 -> 45.5 | H32: =J32*0.4 -> 84 | I32: 70 | J32: 210
C33: 7 - 23 | F33: =J33/I33 -> 3.2857143 | G33: =I33*0.65 -> 45.5 | H33: =J33*0.4 -> 92 | I33: 70 | J33: 230
C34: 8 - 12 | F34: =J34/I34 -> 1.5 | G34: =I34*0.65 -> 52 | H34: =J34*0.4 -> 48 | I34: 80 | J34: 120
C35: 8 - 16 | F35: =J35/I35 -> 2 | G35: =I35*0.65 -> 52 | H35: =J35*0.4 -> 64 | I35: 80 | J35: 160
C36: 8 - 18 | F36: =J36/I36 -> 2.25 | G36: =I36*0.65 -> 52 | H36: =J36*0.4 -> 72 | I36: 80 | J36: 180
... C40: CaCO3 | F40: =J40/I40 -> #DIV/0! | G40: =I40*0.65 -> 0 | H40: =J40*0.4 -> 160 | I40: 0 | J40: 400
E42: =IF(L14=0,ABS(L12)/((G14+1.01)/1000),ABS(L14)/(I14/1000)) -> #VALUE! | G42: =ROUND(E42/5,0)*5 -> #VALUE!

Sheet BILAN
B1: ALIM'ovins(v. 5.1)
B2: Rationnement des ovins
I4: Bilan alimentaire
C7: Saisir l'effectif d'animaux du lot | J7: =ANIMAL!E11 -> Brebis 70 kg Gestante Double Semaines - 3 à - 4 | N7: Cout de concentré (€ / animal / jour)
C10: Saisir la durée d'alimentation (en jours) | P10: =IF(G7="","",(M32/G7)/G10)
C14: QUANTITE DE FOURRAGE | P14: Pour 1 tonne de ration complète
C15: =IF(FOURRAGE!C9="","",FOURRAGE!E9) | K15: =IF(C15="","",(G7*G10*FOURRAGE!L10)/1000) | M15: tonnes (brut) | Q15: =IF(K15="","",IF(K15=0,0,K15/(SUM($K$15,$K$18,$H$26,$H$28,$H$30))*1000)) | R15: kg
C18: =IF(FOURRAGE!C23="","",FOURRAGE!E23) | K18: =IF(C18="","",(G7*G10*FOURRAGE!L24)/1000) | M18: tonnes (brut) | Q18: =IF(K18="","",IF(K18=0,0,K18/(SUM($K$15,$K$18,$H$26,$H$28,$H$30))*1000)) | R18: kg
Q21: Pourcentage de concentré
C23: COUT DE CONCENTRE | G23: kg / jour | H23: Besoins pour la période | K23: Coût | M23: Cout total | Q23: =SUM(Q26,Q28,Q30)/1000 -> 0
K24: unitaire
C26: =IF(CONCENTRE!C10="","",CONCENTRE!C10) | G26: =IF(CONCENTRE!K9="","",CONCENTRE!K9) | H26: =IF(G26="","",(G26*$G$10*$G$7)/1000) | I26: tonnes | L26: / t | M26: =IF(G26="","",K26*H26) | Q26: =IF(K26=0,0,IF(M26="",0,H26/(SUM($K$15,$K$18,$H$26,$H$28,$H$30))*1000)) -> 0 | R26: kg
C28: =IF(CONCENTRE!C17="","",CONCENTRE!C17) | G28: =IF(CONCENTRE!K16="","",CONCENTRE!K16) | H28: =IF(G28="","",(G28*$G$10*$G$7)/1000) | I28: tonnes | L28: / t | M28: =IF(G28="","",K28*H28) | Q28: =IF(K28=0,0,IF(M28="",0,H28/(SUM($K$15,$K$18,$H$26,$H$28,$H$30))*1000)) -> 0 | R28: kg
C30: =IF(CMV!C8="","",CMV!C8) | G30: =IF(CMV!C12="","",CMV!C12/1000) | H30: =IF(G30="","",(G30*$G$10*$G$7)/1000) | I30: tonnes | L30: / t | M30: =IF(G30="","",K30*H30) | Q30: =IF(K30=0,0,IF(M30="",0,H30/(SUM($K$15,$K$18,$H$26,$H$28,$H$30))*1000)) -> 0 | R30: kg
C32: COUT TOTAL DE CONCENTRE (en € pour le lot et pour la période) | M32: =IF($G$7="","",SUM(M26,M28,M30)) | Q32: =SUM(Q30,Q28,Q26,Q18,Q15) -> 0 | R32: kg
E37: =Q15
B40: 1 | C40: Janvier | D40: 2010
B41: 2 | C41: Février | D41: 2011
B42: 3 | C42: Mars | D42: 2012
B43: 4 | C43: Avril | D43: 2013
B44: 5 | C44: Mai | D44: 2014
B45: 6 | C45: Juin | D45: 2015
B46: 7 | C46: Juillet | D46: 2016
B47: 8 | C47: Août
B48: 9 | C48: Septembre
B49: 10 | C49: Octobre
B50: 11 | C50: Novembre
B51: 12 | C51: Décembre
B52: 13
B53: 14
B54: 15
B55: 16
B56: 17
B57: 18
B58: 19
B59: 20
B60: 21
B61: 22
B62: 23
B63: 24
...

Sheet MELANGE
B1: ALIM'ovins(v. 5.0)
B2: Rationnement des bovins allaitants
B5: CALCUL DE LA COMPOSITION D'UN MELANGE DE 2 CONCENTRES
B6: Système de 2 équations et 2 inconnues (x et y)
B8: =IF(E9="","1 Mélange n'est pas nécessaire !",IF(H9<0,"1 Mélange n'est pas nécessaire ! Cliquez sur Retour","")) -> 1 Mélange n'est pas nécessaire ! | E8: =IF(CONCENTRE!C10="","",CONCENTRE!C10) | F8: x | G8: + | H8: =IF(CONCENTRE!C17="","",CONCENTRE!C17) | I8: y
E9: =E24 | F9: kg | H9: =H24 | I9: kg
C11: Déficit | E11: =IF(E9="","",E20/(E20+H20)) | H11: =IF(H9="","",H20/(E20+H20))
B12: UFL | C12: =IF(CONCENTRE!E10="","",-RATION!F18) | D12: = | E12: =IF(CONCENTRE!C10="",0.001,CONCENTRE!E10) -> 0.001 | F12: x | G12: + | H12: =IF(CONCENTRE!C17="",0.001,CONCENTRE!E17) -> 0.001 | I12: y
B14: PDIN | C14: =IF(CONCENTRE!F10="","",-RATION!G18) | D14: = | E14: =IF(CONCENTRE!C10="",0.001,CONCENTRE!F10) -> 0.001 | F14: x | G14: + | H14: =IF(CONCENTRE!C17="",0.001,CONCENTRE!F17) -> 0.001 | I14: y
B16: =IF(E9="","VERIFIER vos concentrés, le mélange n'est pas adapté !",IF(H9="","VERIFIER vos concentrés, le mélange n'est pas adapté !","")) -> VERIFIER vos concentrés, le mélange n'est pas adapté !
E20: =IF((C12-(H12*H20))/E12<0,"",IF(E12=0.001,0,IF(C12<=0.1,0,IF(C12="","",ROUND((C12-(H12*H20))/E12,1))))) -> #VALUE! | H20: =IF((C14-(C12*E14)/E12)/(H14-((H12*E14)/E12))<0,0,IF(H12=0.001,0,IF(C14<=0.1,0,IF(C12="","",ROUND((C14-(C12*E14)/E12)/(H14-((H12*E14)/E12)),1))))) -> #VALUE!
E22: =IF(E12=0.001,0,IF(C12<=0.1,0,IF(C12="","",(C12-(H12*H20))/E12))) -> 0 | H22: =IF(H12=0.001,0,IF(C14<=0.1,0,IF(C12="","",(C14-(C12*E14)/E12)/(H14-((H12*E14)/E12))))) -> 0
E24: =IF(E22<=0,"",IF(H22>0,ROUND(E22,1),ROUND(C12/E12,1))) | H24: =IF(H22<=0,"",IF(E22>0,ROUND(H20,1),ROUND(C12/H12,1)))
C27: (C14-(C12*E14)/E12)/(H14-((H12*E14)/E12))))
C28: (C12-(H12*H9))/E12)
C30: SI(E12=0,001;0;SI(C12<=0,1;0;SI(C12="";"";(C12-(H12*H9))/E12)))
C31: SI(H12=0,001;0;SI(C14<=0,1;0;SI(C12="";"";(C14-(C12*E14)/E12)/(H14-((H12*E14)/E12)))))

Sheet RATION
B1: ALIM'ovins(v. 5.1)
B2: Rationnement des ovins
F4: Ration
B6: Catégorie | E6: Apports Alimentaires Recommandés | L6: REPARTITION DES APPORTS | T6: UFL | U6: PDIN | V6: PDIE | W6: P | X6: Ca
E7: UEM | F7: UFL | G7: PDIN | H7: PDIE | I7: Pabs | J7: Caabs | L7: en % des besoins alimentaires | T7: =F29/F8 -> #VALUE! | U7: =G29/G8 -> #VALUE! | V7: =H29/H8 -> #VALUE! | W7: =I29/I8 -> #VALUE! | X7: =J29/J8 -> #VALUE!
B8: =IF(ANIMAL!E11="","",ANIMAL!E11) -> Brebis 70 kg Gestante Double Semaines - 3 à - 4 | E8: =IF($B$8="","",ANIMAL!E16) -> 1.71 | F8: =IF($B$8="","",ANIMAL!F16) -> 1.14 | G8: =IF($B$8="","",ANIMAL!G16) -> 146 | H8: =IF($B$8="","",ANIMAL!G16) -> 146 | I8: =IF($B$8="","",ANIMAL!H16) -> 3.2 | J8: =IF($B$8="","",ANIMAL!I16) -> 3.5 | T8: 1 | U8: 1 | V8: 1 | W8: 1 | X8: 1
B10: Quantité kg | C10: Aliments (valeurs / kg MS) | D10: Valeurs alimentaires
D11: MS | E11: UEM | F11: UFL | G11: PDIN | H11: PDIE | I11: Pabs | J11: Caabs
B12: =IF(FOURRAGE!L10="","",FOURRAGE!L10) | C12: =FOURRAGE!E9 | D12: =FOURRAGE!E15 | E12: =FOURRAGE!F15 | F12: =FOURRAGE!G15 | G12: =FOURRAGE!H15 | H12: =FOURRAGE!I15 | I12: =FOURRAGE!J15 | J12: =FOURRAGE!L15
D13: =IF(B12="","",B12*(D12/100)) | E13: =IF($D$13="","",$D$13*E12) | F13: =IF($D$13="","",$D$13*F12) | G13: =IF($D$13="","",$D$13*G12) | H13: =IF($D$13="","",$D$13*H12) | I13: =IF($D$13="","",$D$13*I12) | J13: =IF($D$13="","",$D$13*J12) | M13: =F29/F8 -> #VALUE! | N13: =G29/G8 -> #VALUE! | P13: =H29/H8 -> #VALUE! | Q13: =I29/I8 -> #VALUE! | R13: =J29/J8 -> #VALUE!
B14: =IF(FOURRAGE!L24="","",FOURRAGE!L24) | C14: =FOURRAGE!E23 | D14: =IF(C14="","",FOURRAGE!E29) | E14: =IF(C14="","",FOURRAGE!F29) | F14: =IF(C14="","",FOURRAGE!G29) | G14: =IF(C14="","",FOURRAGE!H29) | H14: =IF(C14="","",FOURRAGE!I29) | I14: =IF(C14="","",FOURRAGE!J29) | J14: =IF(C14="","",FOURRAGE!L29) | L14: Part des fourrages et des concentrés dans la ration | O14: MS | Q14: UFL | R14: PDIN
D15: =IF(B14="","",B14*(D14/100)) | E15: =IF($D$15="","",$D$15*E14) | F15: =IF($D$15="","",$D$15*F14) | G15: =IF($D$15="","",$D$15*G14) | H15: =IF($D$15="","",$D$15*H14) | I15: =IF($D$15="","",$D$15*I14) | J15: =IF($D$15="","",$D$15*J14)
B16: =IF(SUM(B12,B14)=0,"",SUM(B12,B14)) | C16: Ration de base | D16: =IF(B16="","",SUM(D13,D15)) | E16: =IF(B16="","",SUM(E13,E15)) | F16: =IF(B16="","",SUM(F13,F15)) | G16: =IF(B16="","",SUM(G13,G15)) | H16: =IF(B16="","",SUM(H13,H15)) | I16: =IF(B16="","",SUM(I13,I15)) | J16: =IF(B16="","",SUM(J13,J15)) | L16: Concentrés
O17: =IF(G7="","",IF(V18=0,"",V18))
B18: Différence | E18: =IF(E8="","",E16-E8) -> #VALUE! | F18: =IF(F8="","",F16-F8) -> #VALUE! | G18: =IF(G8="","",G16-G8) -> #VALUE! | H18: =IF(H8="","",H16-H8) -> #VALUE! | I18: =IF(I8="","",I16-I8) -> #VALUE! | J18: =IF(J8="","",J16-J8) -> #VALUE! | T18: Fourrage 1 | U18: =B12 | V18: =SUM(U18,U19)/SUM(U18,U19,U20,U21,0.0001) -> 0 | W18: =F13 | X18: =SUM(W18,W19)/SUM(W18,W19,W20,W21,0.0001) -> 0 | Y18: =G13 | Z18: =SUM(Y18,Y19)/SUM(Y18,Y19,Y20,Y21,0.0001) -> 0
L19: Fourrages | O19: =IF(V19=0,"",V19) | T19: Fourrage 2 | U19: =B14 | V19: =SUM(U20,U21)/SUM(U18,U19,U20,U21,0.0001) -> 0 | W19: =F15 | X19: =SUM(W20,W21)/SUM(W18,W19,W20,W21,0.0001) -> 0 | Y19: =H15 | Z19: =SUM(Y20,Y21)/SUM(Y18,Y19,Y20,Y21,0.0001) -> 0
B20: =IF(CONCENTRE!K9="","",CONCENTRE!K9) | C20: =IF(B20="","",CONCENTRE!C10) | F20: =IF(C20="","",CONCENTRE!E10) | G20: =IF(C20="","",CONCENTRE!F10) | H20: =IF(C20="","",CONCENTRE!G10) | I20: =IF(C20="","",CONCENTRE!H10) | J20: =IF(C20="","",CONCENTRE!I10) | T20: Concentré 1 | U20: =B20 | W20: =F21 | Y20: =G21
F21: =IF(B20="","",$B$20*F20) | G21: =IF(B20="","",$B$20*G20) | H21: =IF(B20="","",$B$20*H20) | I21: =IF(B20="","",$B$20*I20) | J21: =IF(B20="","",$B$20*J20) | T21: Concentré 2 | U21: =B22 | W21: =F23 | Y21: =G23
B22: =IF(CONCENTRE!K16="","",CONCENTRE!K16) | C22: =IF(B22="","",CONCENTRE!C17) | F22: =IF(C22="","",CONCENTRE!E17) | G22: =IF(C22="","",CONCENTRE!F17) | H22: =IF(C22="","",CONCENTRE!G17) | I22: =IF(C22="","",CONCENTRE!H17) | J22: =IF(C22="","",CONCENTRE!I17)
F23: =IF(B22="","",$B$22*F22) | G23: =IF(B22="","",$B$22*G22) | H23: =IF(B22="","",$B$22*H22) | I23: =IF(B22="","",$B$22*I22) | J23: =IF(B22="","",$B$22*J22) | L23: REPARTITION DES ALIMENTS
B24: =IF(SUM(B20,B22)=0,"",SUM(B20,B22)) | C24: Concentrés | F24: =IF(B24="","",SUM(F21,F23)) | G24: =IF(B24="","",SUM(G21,G23)) | H24: =IF(B24="","",SUM(H21,H23)) | I24: =IF(B24="","",SUM(I21,I23)) | J24: =IF(B24="","",SUM(J21,J23))
B26: RMIC = | C26: PDIN - PDIE | D26: =IF(D29="","",(G29-H29)/F29) | E26: * | F26: =IF(CMV!C8="","",(CMV!C12)/1000) | G26: =IF(F26="","",CMV!L8) | I26: =CMV!G14 | J26: =CMV!I14
C27: UFL | I27: =IF(F26="","",I26*F26) | J27: =IF(F26="","",J26*F26)
B29: =IF(B16="","",SUM(B16,B24,F26)) | C29: TOTAL RATION | D29: =D16 | E29: =E16 | F29: =IF(F18="","",SUM(F24,F16)) -> #VALUE! | G29: =IF(G18="","",SUM(G24,G16)) -> #VALUE! | H29: =IF(H18="","",SUM(H24,H16)) -> #VALUE! | I29: =IF(I18="","",SUM(I24,I16,I27)) -> #VALUE! | J29: =IF(J18="","",SUM(J24,J16,J27)) -> #VALUE!
C31: Différence | E31: =IF(B16="","",E29-E8) | F31: =IF($B$16="","",F29-F8) | G31: =IF($B$16="","",G29-G8) | H31: =IF($B$16="","",H29-H8) | I31: =IF($B$16="","",I29-I8) | J31: =IF($B$16="","",J29-J8)
A32: * RMIC < - 12 (Brebis allaitantes - agneaux simples) RMIC < - 6 (Brebis allaitantes - agneaux doubles) | E32: =IF(E31="","",IF(E31>0.01,"ATTENTION ! La capacité d'ingestion est dépassée: REDUISEZ LES QUANTITES DE FOURRAGE",""))

Sheet COUT
B1: ALIM'ovins(v. 5.1)
B2: Rationnement des ovins
F4: Formulation d'aliment et coût
B5: FORMULATION ET CALCUL DU COUT D'UN MELANGE FERMIER | P5: Répartition des matières premières
B6: Cliquez dans la case "Matières premières" et choisissez dans la liste - Saisissez ensuite les quantités introduites dans le mélange | O6: Coût des matières premières (€ /tonne)
B7: Quantités kg | C7: Matières premières | E7: Valeurs alimentaires
E8: % | F8: UFL | G8: UFV | H8: PDIN | I8: PDIE | J8: Pabs | K8: Caabs | L8: MAT | M8: CB
E9: =IF(B9="","",B9/$B$23) | F9: =IF(B9="","",IF(C9="Mes_concentrés",VLOOKUP(D9,NOUVEAU!$R$22:$AA$38,3),VLOOKUP($D9,$D29:$K76,3))) | G9: =IF(B9="","",IF(C9="Mes_concentrés",VLOOKUP(D9,NOUVEAU!$R$22:$AA$38,4),VLOOKUP($D9,$D29:$K76,4))) | H9: =IF(B9="","",IF(C9="Mes_concentrés",VLOOKUP(D9,NOUVEAU!$R$22:$AA$38,5),VLOOKUP($D9,$D29:$K76,5))) | I9: =IF(B9="","",IF(C9="Mes_concentrés",VLOOKUP(D9,NOUVEAU!$R$22:$AA$38,6),VLOOKUP($D9,$D29:$K76,6))) | J9: =IF(B9="","",IF(C9="Mes_concentrés",VLOOKUP(D9,NOUVEAU!$R$22:$AA$38,7),VLOOKUP($D9,$D29:$K76,7))) | K9: =IF(B9="","",IF(C9="Mes_concentrés",VLOOKUP(D9,NOUVEAU!$R$22:$AA$38,8),VLOOKUP($D9,$D29:$K76,8))) | L9: =IF(B9="","",IF(C9="Mes_concentrés",VLOOKUP(D9,NOUVEAU!$R$22:$AC$38,9),VLOOKUP($D9,$D29:$M76,9))) | M9: =IF(B9="","",IF(C9="Mes_concentrés",VLOOKUP(D9,NOUVEAU!$R$22:$AC$38,10),VLOOKUP($D9,$D29:$M76,10)))
F10: =IF(B9="","",$E$9*F9) | G10: =IF(B9="","",$E$9*G9) | H10: =IF(B9="","",$E$9*H9) | I10: =IF(B9="","",$E$9*I9) | J10: =IF(B9="","",$E$9*J9) | K10: =IF(B9="","",$E$9*K9) | L10: =IF(B9="","",$E$9*L9) | M10: =IF(B9="","",$E$9*M9)
E11: =IF(B9="","",B11/$B$23) | F11: =IF(B11="","",IF(C11="Mes_concentrés",VLOOKUP(D11,NOUVEAU!$R$22:$AA$38,3),VLOOKUP($D11,$D29:$K76,3))) | G11: =IF(B11="","",IF(C11="Mes_concentrés",VLOOKUP(D11,NOUVEAU!$R$22:$AA$38,4),VLOOKUP($D11,$D29:$K76,4))) | H11: =IF(B11="","",IF(C11="Mes_concentrés",VLOOKUP(D11,NOUVEAU!$R$22:$AA$38,5),VLOOKUP($D11,$D29:$K76,5))) | I11: =IF(B11="","",IF(C11="Mes_concentrés",VLOOKUP(D11,NOUVEAU!$R$22:$AA$38,6),VLOOKUP($D11,$D29:$K76,6))) | J11: =IF(B11="","",IF(C11="Mes_concentrés",VLOOKUP(D11,NOUVEAU!$R$22:$AA$38,7),VLOOKUP($D11,$D29:$K76,7))) | K11: =IF(B11="","",IF(C11="Mes_concentrés",VLOOKUP(D11,NOUVEAU!$R$22:$AA$38,8),VLOOKUP($D11,$D29:$K76,8))) | L11: =IF(B11="","",IF(C11="Mes_concentrés",VLOOKUP(D11,NOUVEAU!$R$22:$AC$38,9),VLOOKUP($D11,$D29:$M76,9))) | M11: =IF(B11="","",IF(C11="Mes_concentrés",VLOOKUP(D11,NOUVEAU!$R$22:$AC$38,10),VLOOKUP($D11,$D29:$M76,10)))
F12: =IF(B11="","",E11*F11) | G12: =IF(B11="","",E11*G11) | H12: =IF(B11="","",E11*H11) | I12: =IF(B11="","",E11*I11) | J12: =IF(B11="","",E11*J11) | K12: =IF(B11="","",E11*K11) | L12: =IF(B11="","",E11*L11) | M12: =IF(B11="","",$E$11*M11)
E13: =IF(B9="","",B13/$B$23) | F13: =IF(B13="","",IF(C13="Mes_concentrés",VLOOKUP(D13,NOUVEAU!$R$22:$AA$38,3),VLOOKUP($D13,$D29:$K76,3))) | G13: =IF(B13="","",IF(C13="Mes_concentrés",VLOOKUP(D13,NOUVEAU!$R$22:$AA$38,4),VLOOKUP($D13,$D29:$K76,4))) | H13: =IF(B13="","",IF(C13="Mes_concentrés",VLOOKUP(D13,NOUVEAU!$R$22:$AA$38,5),VLOOKUP($D13,$D29:$K76,5))) | I13: =IF(B13="","",IF(C13="Mes_concentrés",VLOOKUP(D13,NOUVEAU!$R$22:$AA$38,6),VLOOKUP($D13,$D29:$K76,6))) | J13: =IF(B13="","",IF(C13="Mes_concentrés",VLOOKUP(D13,NOUVEAU!$R$22:$AA$38,7),VLOOKUP($D13,$D29:$K76,7))) | K13: =IF(B13="","",IF(C13="Mes_concentrés",VLOOKUP(D13,NOUVEAU!$R$22:$AA$38,8),VLOOKUP($D13,$D29:$K76,8))) | L13: =IF(B13="","",IF(C13="Mes_concentrés",VLOOKUP(D13,NOUVEAU!$R$22:$AC$38,9),VLOOKUP($D13,$D29:$M76,9))) | M13: =IF(B13="","",IF(C13="Mes_concentrés",VLOOKUP(D13,NOUVEAU!$R$22:$AC$38,10),VLOOKUP($D13,$D29:$M76,10)))
F14: =IF(B13="","",E13*F13) | G14: =IF(C13="","",E13*G13) | H14: =IF(B13="","",E13*H13) | I14: =IF(B13="","",E13*I13) | J14: =IF(B13="","",E13*J13) | K14: =IF(B13="","",E13*K13) | L14: =IF(B13="","",E13*L13) | M14: =IF(B13="","",$E$13*M13)
E15: =IF(B9="","",B15/$B$23) | F15: =IF(B15="","",IF(C15="Mes_concentrés",VLOOKUP(D15,NOUVEAU!$R$22:$AA$38,3),VLOOKUP($D15,$D29:$K76,3))) | G15: =IF(B15="","",IF(C15="Mes_concentrés",VLOOKUP(D15,NOUVEAU!$R$22:$AA$38,4),VLOOKUP($D15,$D29:$K76,4))) | H15: =IF(B15="","",IF(C15="Mes_concentrés",VLOOKUP(D15,NOUVEAU!$R$22:$AA$38,5),VLOOKUP($D15,$D29:$K76,5))) | I15: =IF(B15="","",IF(C15="Mes_concentrés",VLOOKUP(D15,NOUVEAU!$R$22:$AA$38,6),VLOOKUP($D15,$D29:$K76,6))) | J15: =IF(B15="","",IF(C15="Mes_concentrés",VLOOKUP(D15,NOUVEAU!$R$22:$AA$38,7),VLOOKUP($D15,$D29:$K76,7))) | K15: =IF(B15="","",IF(C15="Mes_concentrés",VLOOKUP(D15,NOUVEAU!$R$22:$AA$38,8),VLOOKUP($D15,$D29:$K76,8))) | L15: =IF(B15="","",IF(C15="Mes_concentrés",VLOOKUP(D15,NOUVEAU!$R$22:$AC$38,9),VLOOKUP($D15,$D29:$M76,9))) | M15: =IF(B15="","",IF(C15="Mes_concentrés",VLOOKUP(D15,NOUVEAU!$R$22:$AC$38,10),VLOOKUP($D15,$D29:$M76,10)))
F16: =IF(B15="","",E15*F15) | G16: =IF(B15="","",E15*G15) | H16: =IF(B15="","",E15*H15) | I16: =IF(B15="","",E15*I15) | J16: =IF(B15="","",E15*J15) | K16: =IF(B15="","",E15*K15) | L16: =IF(B15="","",E15*L15) | M16: =IF(B15="","",$E$15*M15)
E17: =IF(B9="","",B17/$B$23) | F17: =IF(B17="","",IF(C17="Mes_concentrés",VLOOKUP(D17,NOUVEAU!$R$22:$AA$38,3),VLOOKUP($D17,$D29:$K76,3))) | G17: =IF(B17="","",IF(C17="Mes_concentrés",VLOOKUP(D17,NOUVEAU!$R$22:$AA$38,4),VLOOKUP($D17,$D29:$K76,4))) | H17: =IF(B17="","",IF(C17="Mes_concentrés",VLOOKUP(D17,NOUVEAU!$R$22:$AA$38,5),VLOOKUP($D17,$D29:$K76,5))) | I17: =IF(B17="","",IF(C17="Mes_concentrés",VLOOKUP(D17,NOUVEAU!$R$22:$AA$38,6),VLOOKUP($D17,$D29:$K76,6))) | J17: =IF(B17="","",IF(C17="Mes_concentrés",VLOOKUP(D17,NOUVEAU!$R$22:$AA$38,7),VLOOKUP($D17,$D29:$K76,7))) | K17: =IF(B17="","",IF(C17="Mes_concentrés",VLOOKUP(D17,NOUVEAU!$R$22:$AA$38,8),VLOOKUP($D17,$D29:$K76,8))) | L17: =IF(B17="","",IF(C17="Mes_concentrés",VLOOKUP(D17,NOUVEAU!$R$22:$AC$38,9),VLOOKUP($D17,$D29:$M76,9))) | M17: =IF(B17="","",IF(C17="Mes_concentrés",VLOOKUP(D17,NOUVEAU!$R$22:$AC$38,10),VLOOKUP($D17,$D29:$M76,10)))
F18: =IF(B17="","",E17*F17) | G18: =IF(B17="","",E17*G17) | H18: =IF(B17="","",E17*H17) | I18: =IF(B17="","",E17*I17) | J18: =IF(B17="","",E17*J17) | K18: =IF(B17="","",E17*K17) | L18: =IF(B17="","",E17*L17) | M18: =IF(B17="","",$E$17*M17)
E19: =IF(B9="","",B19/$B$23) | F19: =IF(B19="","",IF(C19="Mes_concentrés",VLOOKUP(D19,NOUVEAU!$R$22:$AA$38,3),VLOOKUP($D19,$D29:$K76,3))) | G19: =IF(B19="","",IF(C19="Mes_concentrés",VLOOKUP(D19,NOUVEAU!$R$22:$AA$38,4),VLOOKUP($D19,$D29:$K76,4))) | H19: =IF(B19="","",IF(C19="Mes_concentrés",VLOOKUP(D19,NOUVEAU!$R$22:$AA$38,5),VLOOKUP($D19,$D29:$K76,5))) | I19: =IF(B19="","",IF(C19="Mes_concentrés",VLOOKUP(D19,NOUVEAU!$R$22:$AA$38,6),VLOOKUP($D19,$D29:$K76,6))) | J19: =IF(B19="","",IF(C19="Mes_concentrés",VLOOKUP(D19,NOUVEAU!$R$22:$AA$38,7),VLOOKUP($D19,$D29:$K76,7))) | K19: =IF(B19="","",IF(C19="Mes_concentrés",VLOOKUP(D19,NOUVEAU!$R$22:$AA$38,8),VLOOKUP($D19,$D29:$K76,8))) | L19: =IF(B19="","",IF(C19="Mes_concentrés",VLOOKUP(D19,NOUVEAU!$R$22:$AC$38,9),VLOOKUP($D19,$D29:$M76,9))) | M19: =IF(B19="","",IF(C19="Mes_concentrés",VLOOKUP(D19,NOUVEAU!$R$22:$AC$38,10),VLOOKUP($D19,$D29:$M76,10)))
F20: =IF(B19="","",E19*F19) | G20: =IF(B19="","",E19*G19) | H20: =IF(B19="","",E19*H19) | I20: =IF(B19="","",E19*I19) | J20: =IF(B19="","",E19*J19) | K20: =IF(B19="","",E19*K19) | L20: =IF(B19="","",E19*L19) | M20: =IF(B19="","",$E$19*M19)
F21: =CONCATENATE(ROUND(H23/F23,0)," PDI / UFL") -> #VALUE! | J21: =CONCATENATE("Ca / P = ",ROUND(K23/J23,1)) -> #VALUE!
O22: COUT € / kg
B23: =SUM(B9:B20) -> 0 | C23: kg | D23: Mon aliment | E23: =IF(B9="","",SUM(E9:E20)) | F23: =IF(F10="","",SUM(F10,F12,F14,F16,F18,F20)) | G23: =IF(G10="","",SUM(G10,G12,G14,G16,G18,G20)) | H23: =IF(H10="","",SUM(H10,H12,H14,H16,H18,H20)) | I23: =IF(I10="","",SUM(I10,I12,I14,I16,I18,I20)) | J23: =IF(J10="","",SUM(J10,J12,J14,J16,J18,J20)) | K23: =IF(K10="","",SUM(K10,K12,K14,K16,K18,K20)) | L23: =IF(L10="","",SUM(L10,L12,L14,L16,L18,L20)) | M23: =IF(M10="","",SUM(M10,M12,M14,M16,M18,M20)) | O23: =IF(B9="","",((O10*B9)+(O12*B11)+(O14*B13)+(O16*B15)+(O18*B17)+(O20*B19))/(B23*1000))
D24: Les valeurs alimentaires sont reportées dans la liste des aliments "Mon aliment"
D28: Catégorie | E28: C | F28: U.F.L. | G28: U.F.V. | H28: P.D.I.N. | I28: P.D.I.E. | J28: Pabs | K28: Caabs | L28: MAT | M28: CB
D29: Avoine | F29: 0.77 | G29: 0.71 | H29: 61 | I29: 61 | J29: 2.7 | K29: 0.7 | L29: 11.1 | M29: 13.8 | Q29: Avoine
D30: Bicarbonate de Na | F30: 0 | G30: 0 | H30: 0 | I30: 0 | J30: 0 | K30: 0 | L30: 0 | M30: 0 | Q30: Blé
B31: Céréale | D31: Blé | F31: 1.02 | G31: 1.02 | H31: 70 | I31: 89 | J31: 2.6 | K31: 0.4 | L31: 12.1 | M31: 2.6 | Q31: Maïs grain
B32: Tourteau | D32: Carbonate de Ca | F32: 0 | G32: 0 | H32: 0 | I32: 0 | J32: 0 | K32: 150 | L32: 0 | M32: 0 | Q32: Orge
B33: Graines | D33: CMV 0 - 27 | F33: 0 | G33: 0 | H33: 0 | I33: 0 | J33: 0 | K33: 108 | L33: 0 | M33: 0 | Q33: Sarrazin
B34: Divers | D34: CMV 10 - 20 | F34: 0 | G34: 0 | H34: 0 | I34: 0 | J34: 65 | K34: 80 | L34: 0 | M34: 0 | Q34: Seigle
B35: Minéraux | D35: CMV 10 - 6 | F35: 0 | G35: 0 | H35: 0 | I35: 0 | J35: 65 | K35: 24 | L35: 0 | M35: 0 | Q35: Sorgho
B36: Mes_concentrés | D36: CMV 12 - 12 | F36: 0 | G36: 0 | H36: 0 | I36: 0 | J36: 78 | K36: 48 | L36: 0 | M36: 0 | Q36: Triticale
B37: Fibres | D37: CMV 12 - 12 | F37: 0 | G37: 0 | H37: 0 | I37: 0 | J37: 78 | K37: 48 | L37: 0 | M37: 0
D38: CMV 2 - 28 | F38: 0 | G38: 0 | H38: 0 | I38: 0 | J38: 13 | K38: 112 | L38: 0 | M38: 0 | Q38: Tourteau d'arachide
D39: CMV 3 - 27 | F39: 0 | G39: 0 | H39: 0 | I39: 0 | J39: 20 | K39: 108 | L39: 0 | M39: 0 | Q39: Tourteau de colza
D40: CMV 4 - 21 | F40: 0 | G40: 0 | H40: 0 | I40: 0 | J40: 26 | K40: 84 | L40: 0 | M40: 0 | Q40: Tourteau de coton
D41: CMV 5 - 20 | F41: 0 | G41: 0 | H41: 0 | I41: 0 | J41: 32 | K41: 80 | L41: 0 | M41: 0 | Q41: Tourteau de lin
D42: CMV 5 - 25 | F42: 0 | G42: 0 | H42: 0 | I42: 0 | J42: 32 | K42: 100 | L42: 0 | M42: 0 | Q42: Tourteau de soja
D43: CMV 6 - 6 | F43: 0 | G43: 0 | H43: 0 | I43: 0 | J43: 39 | K43: 24 | L43: 0 | M43: 0 | Q43: Tourteau de tournesol
D44: CMV 7 - 21 | F44: 0 | G44: 0 | H44: 0 | I44: 0 | J44: 15 | K44: 84 | L44: 0 | M44: 0
...

Sheet IMPRIMER
B2: ALIM'ovins (v. 5.1) | F2: Nom:
B3: Rationnement des ovins allaitants
B7: Catégorie | E7: Apports Alimentaires Recommandés
E8: UEM | F8: UFL | G8: PDIN | H8: PDIE | I8: Pabs | J8: Caabs
B9: =IF(ANIMAL!E11="","",ANIMAL!E11) -> Brebis 70 kg Gestante Double Semaines - 3 à - 4 | E9: =IF($B$9="","",ANIMAL!E16) -> 1.71 | F9: =IF($B$9="","",ANIMAL!F16) -> 1.14 | G9: =IF($B$9="","",ANIMAL!G16) -> 146 | H9: =IF($B$9="","",ANIMAL!G16) -> 146 | I9: =IF($B$9="","",ANIMAL!H16) -> 3.2 | J9: =IF($B$9="","",ANIMAL!I16) -> 3.5
B11: Quantité kg | C11: Aliments (valeurs / kg MS) | D11: Valeurs alimentaires
D12: MS | E12: UEM | F12: UFL | G12: PDIN | H12: PDIE | I12: Pabs | J12: Caabs
B13: =IF(FOURRAGE!L10="","",FOURRAGE!L10) | C13: =FOURRAGE!E9 | D13: =FOURRAGE!E15 | E13: =FOURRAGE!F15 | F13: =FOURRAGE!G15 | G13: =FOURRAGE!H15 | H13: =FOURRAGE!I15 | I13: =FOURRAGE!J15 | J13: =FOURRAGE!L15
D14: =IF(B13="","",B13*(D13/100)) | E14: =IF($D$14="","",$D$14*E13) | F14: =IF($D$14="","",$D$14*F13) | G14: =IF($D$14="","",$D$14*G13) | H14: =IF($D$14="","",$D$14*H13) | I14: =IF($D$14="","",$D$14*I13) | J14: =IF($D$14="","",$D$14*J13)
B15: =IF(FOURRAGE!L24="","",FOURRAGE!L24) | C15: =FOURRAGE!E23 | D15: =IF(C15="","",FOURRAGE!E29) | E15: =IF(C15="","",FOURRAGE!F29) | F15: =IF(C15="","",FOURRAGE!G29) | G15: =IF(C15="","",FOURRAGE!H29) | H15: =IF(C15="","",FOURRAGE!I29) | I15: =IF(C15="","",FOURRAGE!J29) | J15: =IF(C15="","",FOURRAGE!L29)
D16: =IF(B15="","",B15*(D15/100)) | E16: =IF($D$16="","",$D$16*E15) | F16: =IF($D$16="","",$D$16*F15) | G16: =IF($D$16="","",$D$16*G15) | H16: =IF($D$16="","",$D$16*H15) | I16: =IF($D$16="","",$D$16*I15) | J16: =IF($D$16="","",$D$16*J15)
B17: =IF(SUM(B13,B15)=0,"",SUM(B13,B15)) | C17: Ration de base | D17: =IF(B17="","",SUM(D14,D16)) | E17: =IF(B17="","",SUM(E14,E16)) | F17: =IF(B17="","",SUM(F14,F16)) | G17: =IF(B17="","",SUM(G14,G16)) | H17: =IF(B17="","",SUM(H14,H16)) | I17: =IF(B17="","",SUM(I14,I16)) | J17: =IF(B17="","",SUM(J14,J16))
B19: Différence | E19: =IF(E9="","",E17-E9) -> #VALUE! | F19: =IF(F9="","",F17-F9) -> #VALUE! | G19: =IF(G9="","",G17-G9) -> #VALUE! | H19: =IF(H9="","",H17-H9) -> #VALUE! | I19: =IF(I9="","",I17-I9) -> #VALUE! | J19: =IF(J9="","",J17-J9) -> #VALUE!
B21: =IF(CONCENTRE!K9="","",CONCENTRE!K9) | C21: =IF(B21="","",CONCENTRE!C10) | F21: =IF(C21="","",CONCENTRE!E10) | G21: =IF(C21="","",CONCENTRE!F10) | H21: =IF(C21="","",CONCENTRE!G10) | I21: =IF(C21="","",CONCENTRE!H10) | J21: =IF(C21="","",CONCENTRE!I10)
F22: =IF(B21="","",$B$21*F21) | G22: =IF(B21="","",$B$21*G21) | H22: =IF(B21="","",$B$21*H21) | I22: =IF(B21="","",$B$21*I21) | J22: =IF(B21="","",$B$21*J21)
B23: =IF(CONCENTRE!K16="","",CONCENTRE!K16) | C23: =IF(B23="","",CONCENTRE!C17) | F23: =IF(C23="","",CONCENTRE!E17) | G23: =IF(C23="","",CONCENTRE!F17) | H23: =IF(C23="","",CONCENTRE!G17) | I23: =IF(C23="","",CONCENTRE!H17) | J23: =IF(C23="","",CONCENTRE!I17)
F24: =IF(B23="","",$B$23*F23) | G24: =IF(B23="","",$B$23*G23) | H24: =IF(B23="","",$B$23*H23) | I24: =IF(B23="","",$B$23*I23) | J24: =IF(B23="","",$B$23*J23)
B25: =IF(SUM(B21,B23)=0,"",SUM(B21,B23)) | C25: Concentrés | F25: =IF(B25="","",SUM(F22,F24)) | G25: =IF(B25="","",SUM(G22,G24)) | H25: =IF(B25="","",SUM(H22,H24)) | I25: =IF(B25="","",SUM(I22,I24)) | J25: =IF(B25="","",SUM(J22,J24))
B27: RMIC = | C27: PDIN - PDIE | D27: =IF(D30="","",(G30-H30)/F30) | E27: * | F27: =IF(CMV!C8="","",(CMV!C12)/1000) | G27: =IF(F27="","",CMV!L8) | I27: =CMV!G14 | J27: =CMV!I14
C28: UFL | I28: =IF(F27="","",I27*F27) | J28: =IF(F27="","",J27*F27)
B30: =IF(B17="","",SUM(B17,B25,F27)) | C30: TOTAL RATION | D30: =D17 | E30: =E17 | F30: =IF(F19="","",SUM(F25,F17)) -> #VALUE! | G30: =IF(G19="","",SUM(G25,G17)) -> #VALUE! | H30: =IF(H19="","",SUM(H25,H17)) -> #VALUE! | I30: =IF(I19="","",SUM(I25,I17,I28)) -> #VALUE! | J30: =IF(J19="","",SUM(J25,J17,J28)) -> #VALUE!
C32: Différence | E32: =IF(B17="","",E30-E9) | F32: =IF($B$17="","",F30-F9) | G32: =IF($B$17="","",G30-G9) | H32: =IF($B$17="","",H30-H9) | I32: =IF($B$17="","",I30-I9) | J32: =IF($B$17="","",J30-J9)
A33: * RMIC < - 12 (Brebis allaitantes - agneaux simples) RMIC < - 6 (Brebis allaitantes - agneaux doubles) | E33: =IF(E32="","",IF(E32>0,"ATTENTION ! La capacité d'ingestion est dépassée: REDUISEZ LES QUANTITES DE FOURRAGE",""))
A36: Commentaires: . . . . . . . . . . . . . . . . . . . . . . . . . . . . . . . . . . . . . . . . . . . . . . . . . . . . . . . . . . . . . . . . . . . . . . . . . . . .
A38: . . . . . . . . . . . . . . . . . . . . . . . . . . . . . . . . . . . . . . . . . . . . . . . . . . . . . . . . . . . . . . . . . . . . . . . . . . . . . . . . . . . . . . . . . . . . . .
A40: . . . . . . . . . . . . . . . . . . . . . . . . . . . . . . . . . . . . . . . . . . . . . . . . . . . . . . . . . . . . . . . . . . . . . . . . . . . . . . . . . . . . . . . . . . . . . .

Sheet IMPRIMCOUT
B2: ALIM'ovins(v. 5.1)
F3: Nom: | G3: OVIMASH Bélier
B4: FORMULATION ET CALCUL DU COUT D'UN CONCENTRE FERMIER
L5: =COUT!N6 -> 0 | M5: =COUT!O6 -> Coût des matières premières (€ /tonne)
B6: =COUT!B7 -> Quantités kg | C6: =COUT!C7 -> Matières premières | D6: =COUT!E7 -> Valeurs alimentaires
D7: =COUT!E8 -> % | E7: =COUT!F8 -> UFL | F7: =COUT!H8 -> PDIN | G7: =COUT!I8 -> PDIE | H7: =COUT!J8 -> Pabs | I7: =COUT!K8 -> Caabs | J7: MAT | K7: CB
B8: =IF(COUT!B9="","",COUT!B9) | C8: =IF(COUT!D9="","",COUT!D9) | D8: =COUT!E9 | E8: =COUT!F9 | F8: =COUT!H9 | G8: =COUT!I9 | H8: =COUT!J9 | I8: =COUT!K9 | J8: =COUT!L9 | K8: =COUT!M9
E9: =COUT!F10 | F9: =COUT!H10 | G9: =COUT!I10 | H9: =COUT!J10 | I9: =COUT!K10 | J9: =COUT!L10 | K9: =COUT!M10 | M9: =COUT!O10 -> 0
B10: =IF(COUT!B11="","",COUT!B11) | C10: =IF(COUT!D11="","",COUT!D11) | D10: =COUT!E11 | E10: =COUT!F11 | F10: =COUT!H11 | G10: =COUT!I11 | H10: =COUT!J11 | I10: =COUT!K11 | J10: =COUT!L11 | K10: =COUT!M11
E11: =COUT!F12 | F11: =COUT!H12 | G11: =COUT!I12 | H11: =COUT!J12 | I11: =COUT!K12 | J11: =COUT!L12 | K11: =COUT!M12 | M11: =COUT!O12 -> 0
B12: =IF(COUT!B13="","",COUT!B13) | C12: =IF(COUT!D13="","",COUT!D13) | D12: =COUT!E13 | E12: =COUT!F13 | F12: =COUT!H13 | G12: =COUT!I13 | H12: =COUT!J13 | I12: =COUT!K13 | J12: =COUT!L13 | K12: =COUT!M13
E13: =COUT!F14 | F13: =COUT!H14 | G13: =COUT!I14 | H13: =COUT!J14 | I13: =COUT!K14 | J13: =COUT!L14 | K13: =COUT!M14 | M13: =COUT!O14 -> 0
B14: =IF(COUT!B15="","",COUT!B15) | C14: =IF(COUT!D15="","",COUT!D15) | D14: =COUT!E15 | E14: =COUT!F15 | F14: =COUT!H15 | G14: =COUT!I15 | H14: =COUT!J15 | I14: =COUT!K15 | J14: =COUT!L15 | K14: =COUT!M15
E15: =COUT!F16 | F15: =COUT!H16 | G15: =COUT!I16 | H15: =COUT!J16 | I15: =COUT!K16 | J15: =COUT!L16 | K15: =COUT!M16 | M15: =COUT!O16 -> 0
B16: =IF(COUT!B17="","",COUT!B17) | C16: =IF(COUT!D17="","",COUT!D17) | D16: =COUT!E17 | E16: =COUT!F17 | F16: =COUT!H17 | G16: =COUT!I17 | H16: =COUT!J17 | I16: =COUT!K17 | J16: =COUT!L17 | K16: =COUT!M17
E17: =COUT!F18 | F17: =COUT!H18 | G17: =COUT!I18 | H17: =COUT!J18 | I17: =COUT!K18 | J17: =COUT!L18 | K17: =COUT!M18 | M17: =COUT!O18 -> 0
B18: =IF(COUT!B19="","",COUT!B19) | C18: =IF(COUT!D19="","",COUT!D19) | D18: =COUT!E19 | E18: =COUT!F19 | F18: =COUT!H19 | G18: =COUT!I19 | H18: =COUT!J19 | I18: =COUT!K19 | J18: =COUT!L19 | K18: =COUT!M19
E19: =COUT!F20 | F19: =COUT!H20 | G19: =COUT!I20 | H19: =COUT!J20 | I19: =COUT!K20 | J19: =COUT!L20 | K19: =COUT!M20 | M19: =COUT!O20 -> 0
M21: =COUT!O22 -> COUT € / kg
B22: =COUT!B23 -> 0 | C22: =COUT!D23 -> Mon aliment | D22: =COUT!E23 | E22: =COUT!F23 | F22: =COUT!H23 | G22: =COUT!I23 | H22: =COUT!J23 | I22: =COUT!K23 | J22: =COUT!L23 | K22: =COUT!M23 | L22: =COUT!N23 -> 0 | M22: =COUT!O23
C27: Catégorie | D27: C | E27: U.F.L. | F27: P.D.I.N. | G27: P.D.I.E. | H27: Pabs | I27: Caabs
C28: Aliment complet | E28: =#REF! -> #REF! | F28: =#REF! -> #REF! | G28: =#REF! -> #REF! | H28: =#REF! -> #REF! | I28: =#REF! -> #REF!
C29: Aliment divers | E29: =#REF! -> #REF! | F29: =#REF! -> #REF! | G29: =#REF! -> #REF! | H29: =#REF! -> #REF! | I29: =#REF! -> #REF!
C30: Avoine | E30: 0.77 | F30: 61 | G30: 61 | H30: 2.7 | I30: 0.7
C31: Bicarbonate de Na | E31: 0 | F31: 0 | G31: 0 | H31: 0 | I31: 0
C32: Blé | E32: 1.02 | F32: 70 | G32: 89 | H32: 2.6 | I32: 0.4
C33: Carbonate de Ca | E33: 0 | F33: 0 | G33: 0 | H33: 0 | I33: 150
C34: CMV 0 - 27 (Gravelle) | E34: 0 | F34: 0 | G34: 0 | H34: 0 | I34: 108
C35: CMV 10 - 20 | E35: 0 | F35: 0 | G35: 0 | H35: 65 | I35: 80
C36: CMV 10 - 6 | E36: 0 | F36: 0 | G36: 0 | H36: 65 | I36: 24
C37: CMV 12 - 12 | E37: 0 | F37: 0 | G37: 0 | H37: 78 | I37: 48
C38: CMV 12 - 12 | E38: 0 | F38: 0 | G38: 0 | H38: 78 | I38: 48
C39: CMV 4 - 21 | E39: 0 | F39: 0 | G39: 0 | H39: 26 | I39: 84
C40: CMV 5 - 20 | E40: 0 | F40: 0 | G40: 0 | H40: 32 | I40: 80
C41: CMV 5 - 25 | E41: 0 | F41: 0 | G41: 0 | H41: 32 | I41: 100
... C47: CMV 9 - 14 | E47: 0 | F47: 0 | G47: 0 | H47: 58 | I47: 56
C48: Complémentaire azoté | E48: =#REF! -> #REF! | F48: =#REF! -> #REF! | G48: =#REF! -> #REF! | H48: =#REF! -> #REF! | I48: =#REF! -> #REF!
C49: Drêches | E49: 0.76 | F49: 178 | G49: 157 | H49: 4.9 | I49: 1.3
C50: Féverole | E50: 1.03 | F50: 170 | G50: 97 | H50: 4.1 | I50: 0.9
C51: Graines Colza | E51: 1.68 | F51: 12 | G51: 61 | H51: 5.3 | I51: 2.8
...

Sheet AGNEAU
B1: ALIM'ovins(v. 5.1)
B2: Rationnement des ovins
B4: Agneau
U5: 3 Composez votre concentré "agneau"
B6: 1 Cliquez sur les flèches ou cochez les cases | F6: CATEGORIE | L6: CHOIX DU CONCENTRE
U7: % | V7: Matières premières | X7: Valeurs alimentaires
E8: =IF(C12="","",CONCATENATE(IF(I33=1,"mâle","femelle")," de race ",IF(I36=TRUE,"à viande","rustique ou croisée")," poids ",C12," - GMQ ",C14)) | X8: UFV | Y8: PDIN | Z8: PDIE | AA8: Pabs | AB8: Caabs
L9: Valeur U.F.V. de l'aliment | P9: =IF(E8="","",M38) | Q9: =IF(P9="","","UFV / kg") | X9: =IF(U9="","",IF(V9="Mes_concentrés",VLOOKUP(W9,NOUVEAU!$R$22:$AA$38,4),VLOOKUP($W9,$W44:$AC93,3))) | Y9: =IF(U9="","",IF(V9="Mes_concentrés",VLOOKUP(W9,NOUVEAU!$R$22:$AA$38,5),VLOOKUP($W9,$W44:$AC93,4))) | Z9: =IF(U9="","",IF(V9="Mes_concentrés",VLOOKUP(W9,NOUVEAU!$R$22:$AA$38,6),VLOOKUP($W9,$W44:$AC93,5))) | AA9: =IF(U9="","",IF(V9="Mes_concentrés",VLOOKUP(W9,NOUVEAU!$R$22:$AA$38,7),VLOOKUP($W9,$W44:$AC93,6))) | AB9: =IF(U9="","",IF(V9="Mes_concentrés",VLOOKUP(W9,NOUVEAU!$R$22:$AA$38,8),VLOOKUP($W9,$W44:$AC93,7)))
X10: =IF(U9="","",($U$9/100)*X9) | Y10: =IF(U9="","",($U$9/100)*Y9) | Z10: =IF(U9="","",($U$9/100)*Z9) | AA10: =IF(U9="","",($U$9/100)*AA9) | AB10: =IF(U9="","",($U$9/100)*AB9)
